Workbook
Name account_balance_table_header: #REF!
Name NewTaipeiCity: 'Custom分類'!$D$2:$D$30
Name account_list: #REF!
Name account_balance_table: #REF!
Name account_list_with_id: #REF!
Name TaipeiCity: 'Custom分類'!$C$2:$C$13
Name filter_project: #REF!
Name categorized_expense_over_month: #REF!

Sheet room_list
A1: case | B1: room_key | C1: property | D1: room_number | E1: room_type | F1: extension_or_unregistered_building | G1: rental_area | H1: base_rent | I1: vacant_for_rent | J1: room_title | K1: video_link | L1: sorting | M1: specific_public_video | N1: mutex_group | O1: vacant_for_rent_check
A2: {=IFERROR( INDEX(big_rental_contract!A:A, MATCH(C2, big_rental_contract!F:F, 0)), "" )} -> A0001 | B2: RL00002 | C2: 永春四號 | D2: A | E2: 分租雅房 | F2: 無 | G2: 9.38 | H2: 12900 | I2: =IF(O2<>"空房招租中", O2, IF(N2="", "空房招租中", IF(ISNUMBER(SEARCH("分層", E2)), IF(COUNTIFS(N:N, N2, O:O, "<>空房招租中") > 0, "入住中", "空房招租中"), IF(COUNTIFS(N:N, N2, O:O, "<>空房招租中", E:E, "*分層*") > 0, "入住中", IF(COUNTIFS(N:N, N2, O:O, "空房招租中", E:E, "*分層*") > 0, "分層優先(隱藏)", "空房招租中") ) ) ) ) -> 入住中 | L2: =IF(AND(A2="", C2="", D2=""), "Z", "A") -> A | O2: =IF(AND(C2<>"", D2<>""), IF(COUNTIFS(sublease_contract!$C:$C, C2, sublease_contract!$D:$D, "*" & D2 & "*", sublease_contract!$G:$G, "<>已退租") = 0, "空房招租中", IF(COUNTIFS(sublease_contract!$C:$C, C2, sublease_contract!$D:$D, "*" & D2 & "*", sublease_contract!$G:$G, "<>已退租", sublease_contract!$N:$N, ">" & (TODAY()+20)) > 0, "入住中", IF(COUNTIFS(sublease_contract!$C:$C, C2, sublease_contract!$D:$D, "*" & D2 & "*", sublease_contract!$G:$G, "<>已退租", sublease_contract!$N:$N, ">=" & TODAY(), sublease_contract!$N:$N, "<=" & (TODAY()+20)) > 0, MINIFS(sublease_contract!$N:$N, sublease_contract!$C:$C, C2, sublease_contract!$D:$D, "*" & D2 & "*", sublease_contract!$G:$G, "<>已退租", sublease_contract!$N:$N, ">=" & TODAY(), sublease_contract!$N:$N, "<=" & (TODAY()+20)), "入住中"))), "") -> 入住中
A3: {=IFERROR( INDEX(big_rental_contract!A:A, MATCH(C3, big_rental_contract!F:F, 0)), "" )} -> A0001 | B3: RL00003 | C3: 永春四號 | D3: B | E3: 分租雅房 | F3: 無 | G3: 10.56 | H3: 13500 | I3: =IF(O3<>"空房招租中", O3, IF(N3="", "空房招租中", IF(ISNUMBER(SEARCH("分層", E3)), IF(COUNTIFS(N:N, N3, O:O, "<>空房招租中") > 0, "入住中", "空房招租中"), IF(COUNTIFS(N:N, N3, O:O, "<>空房招租中", E:E, "*分層*") > 0, "入住中", IF(COUNTIFS(N:N, N3, O:O, "空房招租中", E:E, "*分層*") > 0, "分層優先(隱藏)", "空房招租中") ) ) ) ) -> 入住中 | L3: =IF(AND(A3="", C3="", D3=""), "Z", "A") -> A | O3: =IF(AND(C3<>"", D3<>""), IF(COUNTIFS(sublease_contract!$C:$C, C3, sublease_contract!$D:$D, "*" & D3 & "*", sublease_contract!$G:$G, "<>已退租") = 0, "空房招租中", IF(COUNTIFS(sublease_contract!$C:$C, C3, sublease_contract!$D:$D, "*" & D3 & "*", sublease_contract!$G:$G, "<>已退租", sublease_contract!$N:$N, ">" & (TODAY()+20)) > 0, "入住中", IF(COUNTIFS(sublease_contract!$C:$C, C3, sublease_contract!$D:$D, "*" & D3 & "*", sublease_contract!$G:$G, "<>已退租", sublease_contract!$N:$N, ">=" & TODAY(), sublease_contract!$N:$N, "<=" & (TODAY()+20)) > 0, MINIFS(sublease_contract!$N:$N, sublease_contract!$C:$C, C3, sublease_contract!$D:$D, "*" & D3 & "*", sublease_contract!$G:$G, "<>已退租", sublease_contract!$N:$N, ">=" & TODAY(), sublease_contract!$N:$N, "<=" & (TODAY()+20)), "入住中"))), "") -> 入住中
A4: {=IFERROR( INDEX(big_rental_contract!A:A, MATCH(C4, big_rental_contract!F:F, 0)), "" )} -> A0001 | B4: RL00004 | C4: 永春四號 | D4: C | E4: 分租雅房 | F4: 無 | G4: 13.39 | H4: 13300 | I4: =IF(O4<>"空房招租中", O4, IF(N4="", "空房招租中", IF(ISNUMBER(SEARCH("分層", E4)), IF(COUNTIFS(N:N, N4, O:O, "<>空房招租中") > 0, "入住中", "空房招租中"), IF(COUNTIFS(N:N, N4, O:O, "<>空房招租中", E:E, "*分層*") > 0, "入住中", IF(COUNTIFS(N:N, N4, O:O, "空房招租中", E:E, "*分層*") > 0, "分層優先(隱藏)", "空房招租中") ) ) ) ) -> 入住中 | L4: =IF(AND(A4="", C4="", D4=""), "Z", "A") -> A | O4: =IF(AND(C4<>"", D4<>""), IF(COUNTIFS(sublease_contract!$C:$C, C4, sublease_contract!$D:$D, "*" & D4 & "*", sublease_contract!$G:$G, "<>已退租") = 0, "空房招租中", IF(COUNTIFS(sublease_contract!$C:$C, C4, sublease_contract!$D:$D, "*" & D4 & "*", sublease_contract!$G:$G, "<>已退租", sublease_contract!$N:$N, ">" & (TODAY()+20)) > 0, "入住中", IF(COUNTIFS(sublease_contract!$C:$C, C4, sublease_contract!$D:$D, "*" & D4 & "*", sublease_contract!$G:$G, "<>已退租", sublease_contract!$N:$N, ">=" & TODAY(), sublease_contract!$N:$N, "<=" & (TODAY()+20)) > 0, MINIFS(sublease_contract!$N:$N, sublease_contract!$C:$C, C4, sublease_contract!$D:$D, "*" & D4 & "*", sublease_contract!$G:$G, "<>已退租", sublease_contract!$N:$N, ">=" & TODAY(), sublease_contract!$N:$N, "<=" & (TODAY()+20)), "入住中"))), "") -> 入住中
A5: {=IFERROR( INDEX(big_rental_contract!A:A, MATCH(C5, big_rental_contract!F:F, 0)), "" )} -> A0001 | B5: RL00005 | C5: 永春四號 | D5: D | E5: 分租雅房 | F5: 無 | G5: 11.47 | H5: 14300 | I5: =IF(O5<>"空房招租中", O5, IF(N5="", "空房招租中", IF(ISNUMBER(SEARCH("分層", E5)), IF(COUNTIFS(N:N, N5, O:O, "<>空房招租中") > 0, "入住中", "空房招租中"), IF(COUNTIFS(N:N, N5, O:O, "<>空房招租中", E:E, "*分層*") > 0, "入住中", IF(COUNTIFS(N:N, N5, O:O, "空房招租中", E:E, "*分層*") > 0, "分層優先(隱藏)", "空房招租中") ) ) ) ) -> 入住中 | L5: =IF(AND(A5="", C5="", D5=""), "Z", "A") -> A | O5: =IF(AND(C5<>"", D5<>""), IF(COUNTIFS(sublease_contract!$C:$C, C5, sublease_contract!$D:$D, "*" & D5 & "*", sublease_contract!$G:$G, "<>已退租") = 0, "空房招租中", IF(COUNTIFS(sublease_contract!$C:$C, C5, sublease_contract!$D:$D, "*" & D5 & "*", sublease_contract!$G:$G, "<>已退租", sublease_contract!$N:$N, ">" & (TODAY()+20)) > 0, "入住中", IF(COUNTIFS(sublease_contract!$C:$C, C5, sublease_contract!$D:$D, "*" & D5 & "*", sublease_contract!$G:$G, "<>已退租", sublease_contract!$N:$N, ">=" & TODAY(), sublease_contract!$N:$N, "<=" & (TODAY()+20)) > 0, MINIFS(sublease_contract!$N:$N, sublease_contract!$C:$C, C5, sublease_contract!$D:$D, "*" & D5 & "*", sublease_contract!$G:$G, "<>已退租", sublease_contract!$N:$N, ">=" & TODAY(), sublease_contract!$N:$N, "<=" & (TODAY()+20)), "入住中"))), "") -> 入住中
A6: {=IFERROR( INDEX(big_rental_contract!A:A, MATCH(C6, big_rental_contract!F:F, 0)), "" )} -> A0002 | B6: RL00006 | C6: 內湖秘境 | D6: A | E6: 分租雅房 | F6: 無 | G6: 11.38 | H6: 12300 | I6: =IF(O6<>"空房招租中", O6, IF(N6="", "空房招租中", IF(ISNUMBER(SEARCH("分層", E6)), IF(COUNTIFS(N:N, N6, O:O, "<>空房招租中") > 0, "入住中", "空房招租中"), IF(COUNTIFS(N:N, N6, O:O, "<>空房招租中", E:E, "*分層*") > 0, "入住中", IF(COUNTIFS(N:N, N6, O:O, "空房招租中", E:E, "*分層*") > 0, "分層優先(隱藏)", "空房招租中") ) ) ) ) -> 入住中 | J6: 面山綠景清幽雅房 | L6: =IF(AND(A6="", C6="", D6=""), "Z", "A") -> A | O6: =IF(AND(C6<>"", D6<>""), IF(COUNTIFS(sublease_contract!$C:$C, C6, sublease_contract!$D:$D, "*" & D6 & "*", sublease_contract!$G:$G, "<>已退租") = 0, "空房招租中", IF(COUNTIFS(sublease_contract!$C:$C, C6, sublease_contract!$D:$D, "*" & D6 & "*", sublease_contract!$G:$G, "<>已退租", sublease_contract!$N:$N, ">" & (TODAY()+20)) > 0, "入住中", IF(COUNTIFS(sublease_contract!$C:$C, C6, sublease_contract!$D:$D, "*" & D6 & "*", sublease_contract!$G:$G, "<>已退租", sublease_contract!$N:$N, ">=" & TODAY(), sublease_contract!$N:$N, "<=" & (TODAY()+20)) > 0, MINIFS(sublease_contract!$N:$N, sublease_contract!$C:$C, C6, sublease_contract!$D:$D, "*" & D6 & "*", sublease_contract!$G:$G, "<>已退租", sublease_contract!$N:$N, ">=" & TODAY(), sublease_contract!$N:$N, "<=" & (TODAY()+20)), "入住中"))), "") -> 入住中
A7: {=IFERROR( INDEX(big_rental_contract!A:A, MATCH(C7, big_rental_contract!F:F, 0)), "" )} -> A0002 | B7: RL00007 | C7: 內湖秘境 | D7: B | E7: 分租雅房 | F7: 無 | G7: 9.21 | H7: 12300 | I7: =IF(O7<>"空房招租中", O7, IF(N7="", "空房招租中", IF(ISNUMBER(SEARCH("分層", E7)), IF(COUNTIFS(N:N, N7, O:O, "<>空房招租中") > 0, "入住中", "空房招租中"), IF(COUNTIFS(N:N, N7, O:O, "<>空房招租中", E:E, "*分層*") > 0, "入住中", IF(COUNTIFS(N:N, N7, O:O, "空房招租中", E:E, "*分層*") > 0, "分層優先(隱藏)", "空房招租中") ) ) ) ) -> 入住中 | J7: 面山綠景清幽雅房 | K7: https://youtube.com/shorts/rd6OLksk1pk | L7: =IF(AND(A7="", C7="", D7=""), "Z", "A") -> A | O7: =IF(AND(C7<>"", D7<>""), IF(COUNTIFS(sublease_contract!$C:$C, C7, sublease_contract!$D:$D, "*" & D7 & "*", sublease_contract!$G:$G, "<>已退租") = 0, "空房招租中", IF(COUNTIFS(sublease_contract!$C:$C, C7, sublease_contract!$D:$D, "*" & D7 & "*", sublease_contract!$G:$G, "<>已退租", sublease_contract!$N:$N, ">" & (TODAY()+20)) > 0, "入住中", IF(COUNTIFS(sublease_contract!$C:$C, C7, sublease_contract!$D:$D, "*" & D7 & "*", sublease_contract!$G:$G, "<>已退租", sublease_contract!$N:$N, ">=" & TODAY(), sublease_contract!$N:$N, "<=" & (TODAY()+20)) > 0, MINIFS(sublease_contract!$N:$N, sublease_contract!$C:$C, C7, sublease_contract!$D:$D, "*" & D7 & "*", sublease_contract!$G:$G, "<>已退租", sublease_contract!$N:$N, ">=" & TODAY(), sublease_contract!$N:$N, "<=" & (TODAY()+20)), "入住中"))), "") -> 入住中
A8: {=IFERROR( INDEX(big_rental_contract!A:A, MATCH(C8, big_rental_contract!F:F, 0)), "" )} -> A0002 | B8: RL00008 | C8: 內湖秘境 | D8: C | E8: 分租雅房 | F8: 無 | G8: 17.59 | H8: 14800 | I8: =IF(O8<>"空房招租中", O8, IF(N8="", "空房招租中", IF(ISNUMBER(SEARCH("分層", E8)), IF(COUNTIFS(N:N, N8, O:O, "<>空房招租中") > 0, "入住中", "空房招租中"), IF(COUNTIFS(N:N, N8, O:O, "<>空房招租中", E:E, "*分層*") > 0, "入住中", IF(COUNTIFS(N:N, N8, O:O, "空房招租中", E:E, "*分層*") > 0, "分層優先(隱藏)", "空房招租中") ) ) ) ) -> 入住中 | L8: =IF(AND(A8="", C8="", D8=""), "Z", "A") -> A | O8: =IF(AND(C8<>"", D8<>""), IF(COUNTIFS(sublease_contract!$C:$C, C8, sublease_contract!$D:$D, "*" & D8 & "*", sublease_contract!$G:$G, "<>已退租") = 0, "空房招租中", IF(COUNTIFS(sublease_contract!$C:$C, C8, sublease_contract!$D:$D, "*" & D8 & "*", sublease_contract!$G:$G, "<>已退租", sublease_contract!$N:$N, ">" & (TODAY()+20)) > 0, "入住中", IF(COUNTIFS(sublease_contract!$C:$C, C8, sublease_contract!$D:$D, "*" & D8 & "*", sublease_contract!$G:$G, "<>已退租", sublease_contract!$N:$N, ">=" & TODAY(), sublease_contract!$N:$N, "<=" & (TODAY()+20)) > 0, MINIFS(sublease_contract!$N:$N, sublease_contract!$C:$C, C8, sublease_contract!$D:$D, "*" & D8 & "*", sublease_contract!$G:$G, "<>已退租", sublease_contract!$N:$N, ">=" & TODAY(), sublease_contract!$N:$N, "<=" & (TODAY()+20)), "入住中"))), "") -> 入住中
A9: {=IFERROR( INDEX(big_rental_contract!A:A, MATCH(C9, big_rental_contract!F:F, 0)), "" )} -> A0002 | B9: RL00009 | C9: 內湖秘境 | D9: D | E9: 分租雅房 | F9: 無 | G9: 13.44 | H9: 13200 | I9: =IF(O9<>"空房招租中", O9, IF(N9="", "空房招租中", IF(ISNUMBER(SEARCH("分層", E9)), IF(COUNTIFS(N:N, N9, O:O, "<>空房招租中") > 0, "入住中", "空房招租中"), IF(COUNTIFS(N:N, N9, O:O, "<>空房招租中", E:E, "*分層*") > 0, "入住中", IF(COUNTIFS(N:N, N9, O:O, "空房招租中", E:E, "*分層*") > 0, "分層優先(隱藏)", "空房招租中") ) ) ) ) -> 入住中 | L9: =IF(AND(A9="", C9="", D9=""), "Z", "A") -> A | O9: =IF(AND(C9<>"", D9<>""), IF(COUNTIFS(sublease_contract!$C:$C, C9, sublease_contract!$D:$D, "*" & D9 & "*", sublease_contract!$G:$G, "<>已退租") = 0, "空房招租中", IF(COUNTIFS(sublease_contract!$C:$C, C9, sublease_contract!$D:$D, "*" & D9 & "*", sublease_contract!$G:$G, "<>已退租", sublease_contract!$N:$N, ">" & (TODAY()+20)) > 0, "入住中", IF(COUNTIFS(sublease_contract!$C:$C, C9, sublease_contract!$D:$D, "*" & D9 & "*", sublease_contract!$G:$G, "<>已退租", sublease_contract!$N:$N, ">=" & TODAY(), sublease_contract!$N:$N, "<=" & (TODAY()+20)) > 0, MINIFS(sublease_contract!$N:$N, sublease_contract!$C:$C, C9, sublease_contract!$D:$D, "*" & D9 & "*", sublease_contract!$G:$G, "<>已退租", sublease_contract!$N:$N, ">=" & TODAY(), sublease_contract!$N:$N, "<=" & (TODAY()+20)), "入住中"))), "") -> 入住中
A10: {=IFERROR( INDEX(big_rental_contract!A:A, MATCH(C10, big_rental_contract!F:F, 0)), "" )} -> A0002 | B10: RL00010 | C10: 內湖秘境 | D10: E | E10: 分租雅房 | F10: 無 | G10: 14.84 | H10: 13600 | I10: =IF(O10<>"空房招租中", O10, IF(N10="", "空房招租中", IF(ISNUMBER(SEARCH("分層", E10)), IF(COUNTIFS(N:N, N10, O:O, "<>空房招租中") > 0, "入住中", "空房招租中"), IF(COUNTIFS(N:N, N10, O:O, "<>空房招租中", E:E, "*分層*") > 0, "入住中", IF(COUNTIFS(N:N, N10, O:O, "空房招租中", E:E, "*分層*") > 0, "分層優先(隱藏)", "空房招租中") ) ) ) ) -> 入住中 | L10: =IF(AND(A10="", C10="", D10=""), "Z", "A") -> A | O10: =IF(AND(C10<>"", D10<>""), IF(COUNTIFS(sublease_contract!$C:$C, C10, sublease_contract!$D:$D, "*" & D10 & "*", sublease_contract!$G:$G, "<>已退租") = 0, "空房招租中", IF(COUNTIFS(sublease_contract!$C:$C, C10, sublease_contract!$D:$D, "*" & D10 & "*", sublease_contract!$G:$G, "<>已退租", sublease_contract!$N:$N, ">" & (TODAY()+20)) > 0, "入住中", IF(COUNTIFS(sublease_contract!$C:$C, C10, sublease_contract!$D:$D, "*" & D10 & "*", sublease_contract!$G:$G, "<>已退租", sublease_contract!$N:$N, ">=" & TODAY(), sublease_contract!$N:$N, "<=" & (TODAY()+20)) > 0, MINIFS(sublease_contract!$N:$N, sublease_contract!$C:$C, C10, sublease_contract!$D:$D, "*" & D10 & "*", sublease_contract!$G:$G, "<>已退租", sublease_contract!$N:$N, ">=" & TODAY(), sublease_contract!$N:$N, "<=" & (TODAY()+20)), "入住中"))), "") -> 入住中
A11: {=IFERROR( INDEX(big_rental_contract!A:A, MATCH(C11, big_rental_contract!F:F, 0)), "" )} -> A0002 | B11: RL00011 | C11: 內湖秘境 | D11: F | E11: 分租雅房 | F11: 頂加 | G11: 11.8 | H11: 13500 | I11: =IF(O11<>"空房招租中", O11, IF(N11="", "空房招租中", IF(ISNUMBER(SEARCH("分層", E11)), IF(COUNTIFS(N:N, N11, O:O, "<>空房招租中") > 0, "入住中", "空房招租中"), IF(COUNTIFS(N:N, N11, O:O, "<>空房招租中", E:E, "*分層*") > 0, "入住中", IF(COUNTIFS(N:N, N11, O:O, "空房招租中", E:E, "*分層*") > 0, "分層優先(隱藏)", "空房招租中") ) ) ) ) -> 入住中 | L11: =IF(AND(A11="", C11="", D11=""), "Z", "A") -> A | O11: =IF(AND(C11<>"", D11<>""), IF(COUNTIFS(sublease_contract!$C:$C, C11, sublease_contract!$D:$D, "*" & D11 & "*", sublease_contract!$G:$G, "<>已退租") = 0, "空房招租中", IF(COUNTIFS(sublease_contract!$C:$C, C11, sublease_contract!$D:$D, "*" & D11 & "*", sublease_contract!$G:$G, "<>已退租", sublease_contract!$N:$N, ">" & (TODAY()+20)) > 0, "入住中", IF(COUNTIFS(sublease_contract!$C:$C, C11, sublease_contract!$D:$D, "*" & D11 & "*", sublease_contract!$G:$G, "<>已退租", sublease_contract!$N:$N, ">=" & TODAY(), sublease_contract!$N:$N, "<=" & (TODAY()+20)) > 0, MINIFS(sublease_contract!$N:$N, sublease_contract!$C:$C, C11, sublease_contract!$D:$D, "*" & D11 & "*", sublease_contract!$G:$G, "<>已退租", sublease_contract!$N:$N, ">=" & TODAY(), sublease_contract!$N:$N, "<=" & (TODAY()+20)), "入住中"))), "") -> 入住中
A12: {=IFERROR( INDEX(big_rental_contract!A:A, MATCH(C12, big_rental_contract!F:F, 0)), "" )} -> A0002 | B12: RL00012 | C12: 內湖秘境 | D12: G | E12: 分租雅房 | F12: 頂加 | G12: 11.26 | H12: 12600 | I12: =IF(O12<>"空房招租中", O12, IF(N12="", "空房招租中", IF(ISNUMBER(SEARCH("分層", E12)), IF(COUNTIFS(N:N, N12, O:O, "<>空房招租中") > 0, "入住中", "空房招租中"), IF(COUNTIFS(N:N, N12, O:O, "<>空房招租中", E:E, "*分層*") > 0, "入住中", IF(COUNTIFS(N:N, N12, O:O, "空房招租中", E:E, "*分層*") > 0, "分層優先(隱藏)", "空房招租中") ) ) ) ) -> 入住中 | L12: =IF(AND(A12="", C12="", D12=""), "Z", "A") -> A | O12: =IF(AND(C12<>"", D12<>""), IF(COUNTIFS(sublease_contract!$C:$C, C12, sublease_contract!$D:$D, "*" & D12 & "*", sublease_contract!$G:$G, "<>已退租") = 0, "空房招租中", IF(COUNTIFS(sublease_contract!$C:$C, C12, sublease_contract!$D:$D, "*" & D12 & "*", sublease_contract!$G:$G, "<>已退租", sublease_contract!$N:$N, ">" & (TODAY()+20)) > 0, "入住中", IF(COUNTIFS(sublease_contract!$C:$C, C12, sublease_contract!$D:$D, "*" & D12 & "*", sublease_contract!$G:$G, "<>已退租", sublease_contract!$N:$N, ">=" & TODAY(), sublease_contract!$N:$N, "<=" & (TODAY()+20)) > 0, MINIFS(sublease_contract!$N:$N, sublease_contract!$C:$C, C12, sublease_contract!$D:$D, "*" & D12 & "*", sublease_contract!$G:$G, "<>已退租", sublease_contract!$N:$N, ">=" & TODAY(), sublease_contract!$N:$N, "<=" & (TODAY()+20)), "入住中"))), "") -> 入住中
A13: {=IFERROR( INDEX(big_rental_contract!A:A, MATCH(C13, big_rental_contract!F:F, 0)), "" )} -> A0003 | B13: RL00017 | C13: 龍江229 | D13: A | E13: 分租雅房 | F13: 無 | G13: 8.58 | H13: 13800 | I13: =IF(O13<>"空房招租中", O13, IF(N13="", "空房招租中", IF(ISNUMBER(SEARCH("分層", E13)), IF(COUNTIFS(N:N, N13, O:O, "<>空房招租中") > 0, "入住中", "空房招租中"), IF(COUNTIFS(N:N, N13, O:O, "<>空房招租中", E:E, "*分層*") > 0, "入住中", IF(COUNTIFS(N:N, N13, O:O, "空房招租中", E:E, "*分層*") > 0, "分層優先(隱藏)", "空房招租中") ) ) ) ) -> 入住中 | J13: 採光陽台雅房 | K13: https://youtube.com/shorts/f__aKIJfxsI?si=_5d10MINdTP7j2Da | L13: =IF(AND(A13="", C13="", D13=""), "Z", "A") -> A | O13: =IF(AND(C13<>"", D13<>""), IF(COUNTIFS(sublease_contract!$C:$C, C13, sublease_contract!$D:$D, "*" & D13 & "*", sublease_contract!$G:$G, "<>已退租") = 0, "空房招租中", IF(COUNTIFS(sublease_contract!$C:$C, C13, sublease_contract!$D:$D, "*" & D13 & "*", sublease_contract!$G:$G, "<>已退租", sublease_contract!$N:$N, ">" & (TODAY()+20)) > 0, "入住中", IF(COUNTIFS(sublease_contract!$C:$C, C13, sublease_contract!$D:$D, "*" & D13 & "*", sublease_contract!$G:$G, "<>已退租", sublease_contract!$N:$N, ">=" & TODAY(), sublease_contract!$N:$N, "<=" & (TODAY()+20)) > 0, MINIFS(sublease_contract!$N:$N, sublease_contract!$C:$C, C13, sublease_contract!$D:$D, "*" & D13 & "*", sublease_contract!$G:$G, "<>已退租", sublease_contract!$N:$N, ">=" & TODAY(), sublease_contract!$N:$N, "<=" & (TODAY()+20)), "入住中"))), "") -> 入住中
A14: {=IFERROR( INDEX(big_rental_contract!A:A, MATCH(C14, big_rental_contract!F:F, 0)), "" )} -> A0003 | B14: RL00018 | C14: 龍江229 | D14: B | E14: 分租雅房 | F14: 無 | G14: 8.86 | H14: 13500 | I14: =IF(O14<>"空房招租中", O14, IF(N14="", "空房招租中", IF(ISNUMBER(SEARCH("分層", E14)), IF(COUNTIFS(N:N, N14, O:O, "<>空房招租中") > 0, "入住中", "空房招租中"), IF(COUNTIFS(N:N, N14, O:O, "<>空房招租中", E:E, "*分層*") > 0, "入住中", IF(COUNTIFS(N:N, N14, O:O, "空房招租中", E:E, "*分層*") > 0, "分層優先(隱藏)", "空房招租中") ) ) ) ) -> 入住中 | J14: 採光陽台雅房 | K14: https://youtube.com/shorts/HCk9m8FNmF0?si=FaWFCcxbs1UKny1L | L14: =IF(AND(A14="", C14="", D14=""), "Z", "A") -> A | O14: =IF(AND(C14<>"", D14<>""), IF(COUNTIFS(sublease_contract!$C:$C, C14, sublease_contract!$D:$D, "*" & D14 & "*", sublease_contract!$G:$G, "<>已退租") = 0, "空房招租中", IF(COUNTIFS(sublease_contract!$C:$C, C14, sublease_contract!$D:$D, "*" & D14 & "*", sublease_contract!$G:$G, "<>已退租", sublease_contract!$N:$N, ">" & (TODAY()+20)) > 0, "入住中", IF(COUNTIFS(sublease_contract!$C:$C, C14, sublease_contract!$D:$D, "*" & D14 & "*", sublease_contract!$G:$G, "<>已退租", sublease_contract!$N:$N, ">=" & TODAY(), sublease_contract!$N:$N, "<=" & (TODAY()+20)) > 0, MINIFS(sublease_contract!$N:$N, sublease_contract!$C:$C, C14, sublease_contract!$D:$D, "*" & D14 & "*", sublease_contract!$G:$G, "<>已退租", sublease_contract!$N:$N, ">=" & TODAY(), sublease_contract!$N:$N, "<=" & (TODAY()+20)), "入住中"))), "") -> 入住中
A15: {=IFERROR( INDEX(big_rental_contract!A:A, MATCH(C15, big_rental_contract!F:F, 0)), "" )} -> A0003 | B15: RL00019 | C15: 龍江229 | D15: C | E15: 分租套房 | F15: 無 | G15: 14.58 | H15: 18800 | I15: =IF(O15<>"空房招租中", O15, IF(N15="", "空房招租中", IF(ISNUMBER(SEARCH("分層", E15)), IF(COUNTIFS(N:N, N15, O:O, "<>空房招租中") > 0, "入住中", "空房招租中"), IF(COUNTIFS(N:N, N15, O:O, "<>空房招租中", E:E, "*分層*") > 0, "入住中", IF(COUNTIFS(N:N, N15, O:O, "空房招租中", E:E, "*分層*") > 0, "分層優先(隱藏)", "空房招租中") ) ) ) ) -> 入住中 | J15: 全實牆大樹景採光高級大浴室套房 | K15: https://youtube.com/shorts/kl5RXn92Rrs?feature=share | L15: =IF(AND(A15="", C15="", D15=""), "Z", "A") -> A | O15: =IF(AND(C15<>"", D15<>""), IF(COUNTIFS(sublease_contract!$C:$C, C15, sublease_contract!$D:$D, "*" & D15 & "*", sublease_contract!$G:$G, "<>已退租") = 0, "空房招租中", IF(COUNTIFS(sublease_contract!$C:$C, C15, sublease_contract!$D:$D, "*" & D15 & "*", sublease_contract!$G:$G, "<>已退租", sublease_contract!$N:$N, ">" & (TODAY()+20)) > 0, "入住中", IF(COUNTIFS(sublease_contract!$C:$C, C15, sublease_contract!$D:$D, "*" & D15 & "*", sublease_contract!$G:$G, "<>已退租", sublease_contract!$N:$N, ">=" & TODAY(), sublease_contract!$N:$N, "<=" & (TODAY()+20)) > 0, MINIFS(sublease_contract!$N:$N, sublease_contract!$C:$C, C15, sublease_contract!$D:$D, "*" & D15 & "*", sublease_contract!$G:$G, "<>已退租", sublease_contract!$N:$N, ">=" & TODAY(), sublease_contract!$N:$N, "<=" & (TODAY()+20)), "入住中"))), "") -> 入住中
A16: {=IFERROR( INDEX(big_rental_contract!A:A, MATCH(C16, big_rental_contract!F:F, 0)), "" )} -> A0003 | B16: RL00020 | C16: 龍江229 | D16: D | E16: 分租雅房 | F16: 無 | G16: 8.85 | H16: 13300 | I16: =IF(O16<>"空房招租中", O16, IF(N16="", "空房招租中", IF(ISNUMBER(SEARCH("分層", E16)), IF(COUNTIFS(N:N, N16, O:O, "<>空房招租中") > 0, "入住中", "空房招租中"), IF(COUNTIFS(N:N, N16, O:O, "<>空房招租中", E:E, "*分層*") > 0, "入住中", IF(COUNTIFS(N:N, N16, O:O, "空房招租中", E:E, "*分層*") > 0, "分層優先(隱藏)", "空房招租中") ) ) ) ) -> 入住中 | J16: 全實牆雅房 | L16: =IF(AND(A16="", C16="", D16=""), "Z", "A") -> A | O16: =IF(AND(C16<>"", D16<>""), IF(COUNTIFS(sublease_contract!$C:$C, C16, sublease_contract!$D:$D, "*" & D16 & "*", sublease_contract!$G:$G, "<>已退租") = 0, "空房招租中", IF(COUNTIFS(sublease_contract!$C:$C, C16, sublease_contract!$D:$D, "*" & D16 & "*", sublease_contract!$G:$G, "<>已退租", sublease_contract!$N:$N, ">" & (TODAY()+20)) > 0, "入住中", IF(COUNTIFS(sublease_contract!$C:$C, C16, sublease_contract!$D:$D, "*" & D16 & "*", sublease_contract!$G:$G, "<>已退租", sublease_contract!$N:$N, ">=" & TODAY(), sublease_contract!$N:$N, "<=" & (TODAY()+20)) > 0, MINIFS(sublease_contract!$N:$N, sublease_contract!$C:$C, C16, sublease_contract!$D:$D, "*" & D16 & "*", sublease_contract!$G:$G, "<>已退租", sublease_contract!$N:$N, ">=" & TODAY(), sublease_contract!$N:$N, "<=" & (TODAY()+20)), "入住中"))), "") -> 入住中
A17: {=IFERROR( INDEX(big_rental_contract!A:A, MATCH(C17, big_rental_contract!F:F, 0)), "" )} -> A0003 | B17: RL00021 | C17: 龍江229 | D17: E | E17: 分租雅房 | F17: 無 | G17: 7.69 | H17: 11500 | I17: =IF(O17<>"空房招租中", O17, IF(N17="", "空房招租中", IF(ISNUMBER(SEARCH("分層", E17)), IF(COUNTIFS(N:N, N17, O:O, "<>空房招租中") > 0, "入住中", "空房招租中"), IF(COUNTIFS(N:N, N17, O:O, "<>空房招租中", E:E, "*分層*") > 0, "入住中", IF(COUNTIFS(N:N, N17, O:O, "空房招租中", E:E, "*分層*") > 0, "分層優先(隱藏)", "空房招租中") ) ) ) ) -> 入住中 | J17: 全實牆方正小雅房 | K17: https://youtu.be/HKUVG1fCFzg?si=sbMTrUIXQ4L8SwwB | L17: =IF(AND(A17="", C17="", D17=""), "Z", "A") -> A | O17: =IF(AND(C17<>"", D17<>""), IF(COUNTIFS(sublease_contract!$C:$C, C17, sublease_contract!$D:$D, "*" & D17 & "*", sublease_contract!$G:$G, "<>已退租") = 0, "空房招租中", IF(COUNTIFS(sublease_contract!$C:$C, C17, sublease_contract!$D:$D, "*" & D17 & "*", sublease_contract!$G:$G, "<>已退租", sublease_contract!$N:$N, ">" & (TODAY()+20)) > 0, "入住中", IF(COUNTIFS(sublease_contract!$C:$C, C17, sublease_contract!$D:$D, "*" & D17 & "*", sublease_contract!$G:$G, "<>已退租", sublease_contract!$N:$N, ">=" & TODAY(), sublease_contract!$N:$N, "<=" & (TODAY()+20)) > 0, MINIFS(sublease_contract!$N:$N, sublease_contract!$C:$C, C17, sublease_contract!$D:$D, "*" & D17 & "*", sublease_contract!$G:$G, "<>已退租", sublease_contract!$N:$N, ">=" & TODAY(), sublease_contract!$N:$N, "<=" & (TODAY()+20)), "入住中"))), "") -> 入住中
A18: {=IFERROR( INDEX(big_rental_contract!A:A, MATCH(C18, big_rental_contract!F:F, 0)), "" )} -> A0004 | B18: RL00022 | C18: 哈拉對面 | D18: A | E18: 分租雅房 | F18: 無 | G18: 7.18 | H18: 11000 | I18: =IF(O18<>"空房招租中", O18, IF(N18="", "空房招租中", IF(ISNUMBER(SEARCH("分層", E18)), IF(COUNTIFS(N:N, N18, O:O, "<>空房招租中") > 0, "入住中", "空房招租中"), IF(COUNTIFS(N:N, N18, O:O, "<>空房招租中", E:E, "*分層*") > 0, "入住中", IF(COUNTIFS(N:N, N18, O:O, "空房招租中", E:E, "*分層*") > 0, "分層優先(隱藏)", "空房招租中") ) ) ) ) -> 入住中 | J18: 落地採光窗雅房 | K18: https://youtu.be/_KXCqnnWhgw | L18: =IF(AND(A18="", C18="", D18=""), "Z", "A") -> A | O18: =IF(AND(C18<>"", D18<>""), IF(COUNTIFS(sublease_contract!$C:$C, C18, sublease_contract!$D:$D, "*" & D18 & "*", sublease_contract!$G:$G, "<>已退租") = 0, "空房招租中", IF(COUNTIFS(sublease_contract!$C:$C, C18, sublease_contract!$D:$D, "*" & D18 & "*", sublease_contract!$G:$G, "<>已退租", sublease_contract!$N:$N, ">" & (TODAY()+20)) > 0, "入住中", IF(COUNTIFS(sublease_contract!$C:$C, C18, sublease_contract!$D:$D, "*" & D18 & "*", sublease_contract!$G:$G, "<>已退租", sublease_contract!$N:$N, ">=" & TODAY(), sublease_contract!$N:$N, "<=" & (TODAY()+20)) > 0, MINIFS(sublease_contract!$N:$N, sublease_contract!$C:$C, C18, sublease_contract!$D:$D, "*" & D18 & "*", sublease_contract!$G:$G, "<>已退租", sublease_contract!$N:$N, ">=" & TODAY(), sublease_contract!$N:$N, "<=" & (TODAY()+20)), "入住中"))), "") -> 入住中
A19: {=IFERROR( INDEX(big_rental_contract!A:A, MATCH(C19, big_rental_contract!F:F, 0)), "" )} -> A0004 | B19: RL00023 | C19: 哈拉對面 | D19: B | E19: 分租套房 | F19: 無 | G19: 14.56 | H19: 15800 | I19: =IF(O19<>"空房招租中", O19, IF(N19="", "空房招租中", IF(ISNUMBER(SEARCH("分層", E19)), IF(COUNTIFS(N:N, N19, O:O, "<>空房招租中") > 0, "入住中", "空房招租中"), IF(COUNTIFS(N:N, N19, O:O, "<>空房招租中", E:E, "*分層*") > 0, "入住中", IF(COUNTIFS(N:N, N19, O:O, "空房招租中", E:E, "*分層*") > 0, "分層優先(隱藏)", "空房招租中") ) ) ) ) -> 入住中 | J19: 雙人床採光大套房 | K19: https://youtu.be/5cuncaRJsgQ | L19: =IF(AND(A19="", C19="", D19=""), "Z", "A") -> A | O19: =IF(AND(C19<>"", D19<>""), IF(COUNTIFS(sublease_contract!$C:$C, C19, sublease_contract!$D:$D, "*" & D19 & "*", sublease_contract!$G:$G, "<>已退租") = 0, "空房招租中", IF(COUNTIFS(sublease_contract!$C:$C, C19, sublease_contract!$D:$D, "*" & D19 & "*", sublease_contract!$G:$G, "<>已退租", sublease_contract!$N:$N, ">" & (TODAY()+20)) > 0, "入住中", IF(COUNTIFS(sublease_contract!$C:$C, C19, sublease_contract!$D:$D, "*" & D19 & "*", sublease_contract!$G:$G, "<>已退租", sublease_contract!$N:$N, ">=" & TODAY(), sublease_contract!$N:$N, "<=" & (TODAY()+20)) > 0, MINIFS(sublease_contract!$N:$N, sublease_contract!$C:$C, C19, sublease_contract!$D:$D, "*" & D19 & "*", sublease_contract!$G:$G, "<>已退租", sublease_contract!$N:$N, ">=" & TODAY(), sublease_contract!$N:$N, "<=" & (TODAY()+20)), "入住中"))), "") -> 入住中
A20: {=IFERROR( INDEX(big_rental_contract!A:A, MATCH(C20, big_rental_contract!F:F, 0)), "" )} -> A0004 | B20: RL00024 | C20: 哈拉對面 | D20: C | E20: 分租雅房 | F20: 無 | G20: 8.68 | H20: 11800 | I20: =IF(O20<>"空房招租中", O20, IF(N20="", "空房招租中", IF(ISNUMBER(SEARCH("分層", E20)), IF(COUNTIFS(N:N, N20, O:O, "<>空房招租中") > 0, "入住中", "空房招租中"), IF(COUNTIFS(N:N, N20, O:O, "<>空房招租中", E:E, "*分層*") > 0, "入住中", IF(COUNTIFS(N:N, N20, O:O, "空房招租中", E:E, "*分層*") > 0, "分層優先(隱藏)", "空房招租中") ) ) ) ) -> 入住中 | J20: 全實牆衣櫃雅房 | K20: https://youtu.be/sypXJ2lqQ3o | L20: =IF(AND(A20="", C20="", D20=""), "Z", "A") -> A | O20: =IF(AND(C20<>"", D20<>""), IF(COUNTIFS(sublease_contract!$C:$C, C20, sublease_contract!$D:$D, "*" & D20 & "*", sublease_contract!$G:$G, "<>已退租") = 0, "空房招租中", IF(COUNTIFS(sublease_contract!$C:$C, C20, sublease_contract!$D:$D, "*" & D20 & "*", sublease_contract!$G:$G, "<>已退租", sublease_contract!$N:$N, ">" & (TODAY()+20)) > 0, "入住中", IF(COUNTIFS(sublease_contract!$C:$C, C20, sublease_contract!$D:$D, "*" & D20 & "*", sublease_contract!$G:$G, "<>已退租", sublease_contract!$N:$N, ">=" & TODAY(), sublease_contract!$N:$N, "<=" & (TODAY()+20)) > 0, MINIFS(sublease_contract!$N:$N, sublease_contract!$C:$C, C20, sublease_contract!$D:$D, "*" & D20 & "*", sublease_contract!$G:$G, "<>已退租", sublease_contract!$N:$N, ">=" & TODAY(), sublease_contract!$N:$N, "<=" & (TODAY()+20)), "入住中"))), "") -> 入住中
A21: {=IFERROR( INDEX(big_rental_contract!A:A, MATCH(C21, big_rental_contract!F:F, 0)), "" )} -> A0004 | B21: RL00025 | C21: 哈拉對面 | D21: D | E21: 分租雅房 | F21: 無 | G21: 8.13 | H21: 12300 | I21: =IF(O21<>"空房招租中", O21, IF(N21="", "空房招租中", IF(ISNUMBER(SEARCH("分層", E21)), IF(COUNTIFS(N:N, N21, O:O, "<>空房招租中") > 0, "入住中", "空房招租中"), IF(COUNTIFS(N:N, N21, O:O, "<>空房招租中", E:E, "*分層*") > 0, "入住中", IF(COUNTIFS(N:N, N21, O:O, "空房招租中", E:E, "*分層*") > 0, "分層優先(隱藏)", "空房招租中") ) ) ) ) -> 入住中 | J21: 大大大衣櫃雅房 | K21: https://youtube.com/shorts/7DcBnbE-QfQ?si=vKq2e4gpMYhtGy7W | L21: =IF(AND(A21="", C21="", D21=""), "Z", "A") -> A | O21: =IF(AND(C21<>"", D21<>""), IF(COUNTIFS(sublease_contract!$C:$C, C21, sublease_contract!$D:$D, "*" & D21 & "*", sublease_contract!$G:$G, "<>已退租") = 0, "空房招租中", IF(COUNTIFS(sublease_contract!$C:$C, C21, sublease_contract!$D:$D, "*" & D21 & "*", sublease_contract!$G:$G, "<>已退租", sublease_contract!$N:$N, ">" & (TODAY()+20)) > 0, "入住中", IF(COUNTIFS(sublease_contract!$C:$C, C21, sublease_contract!$D:$D, "*" & D21 & "*", sublease_contract!$G:$G, "<>已退租", sublease_contract!$N:$N, ">=" & TODAY(), sublease_contract!$N:$N, "<=" & (TODAY()+20)) > 0, MINIFS(sublease_contract!$N:$N, sublease_contract!$C:$C, C21, sublease_contract!$D:$D, "*" & D21 & "*", sublease_contract!$G:$G, "<>已退租", sublease_contract!$N:$N, ">=" & TODAY(), sublease_contract!$N:$N, "<=" & (TODAY()+20)), "入住中"))), "") -> 入住中
A22: {=IFERROR( INDEX(big_rental_contract!A:A, MATCH(C22, big_rental_contract!F:F, 0)), "" )} -> A0005 | B22: RL00026 | C22: 北醫醫師府 | D22: A | E22: 分租雅房 | F22: 無 | G22: 8.95 | H22: 13000 | I22: =IF(O22<>"空房招租中", O22, IF(N22="", "空房招租中", IF(ISNUMBER(SEARCH("分層", E22)), IF(COUNTIFS(N:N, N22, O:O, "<>空房招租中") > 0, "入住中", "空房招租中"), IF(COUNTIFS(N:N, N22, O:O, "<>空房招租中", E:E, "*分層*") > 0, "入住中", IF(COUNTIFS(N:N, N22, O:O, "空房招租中", E:E, "*分層*") > 0, "分層優先(隱藏)", "空房招租中") ) ) ) ) -> 入住中 | K22: https://youtube.com/shorts/Hc8fDLPxR2s?si=yi_8BaevlJvKThX8 | L22: =IF(AND(A22="", C22="", D22=""), "Z", "A") -> A | O22: =IF(AND(C22<>"", D22<>""), IF(COUNTIFS(sublease_contract!$C:$C, C22, sublease_contract!$D:$D, "*" & D22 & "*", sublease_contract!$G:$G, "<>已退租") = 0, "空房招租中", IF(COUNTIFS(sublease_contract!$C:$C, C22, sublease_contract!$D:$D, "*" & D22 & "*", sublease_contract!$G:$G, "<>已退租", sublease_contract!$N:$N, ">" & (TODAY()+20)) > 0, "入住中", IF(COUNTIFS(sublease_contract!$C:$C, C22, sublease_contract!$D:$D, "*" & D22 & "*", sublease_contract!$G:$G, "<>已退租", sublease_contract!$N:$N, ">=" & TODAY(), sublease_contract!$N:$N, "<=" & (TODAY()+20)) > 0, MINIFS(sublease_contract!$N:$N, sublease_contract!$C:$C, C22, sublease_contract!$D:$D, "*" & D22 & "*", sublease_contract!$G:$G, "<>已退租", sublease_contract!$N:$N, ">=" & TODAY(), sublease_contract!$N:$N, "<=" & (TODAY()+20)), "入住中"))), "") -> 入住中
A23: {=IFERROR( INDEX(big_rental_contract!A:A, MATCH(C23, big_rental_contract!F:F, 0)), "" )} -> A0005 | B23: RL00027 | C23: 北醫醫師府 | D23: B | E23: 分租套房 | F23: 無 | G23: 14.27 | H23: 17800 | I23: =IF(O23<>"空房招租中", O23, IF(N23="", "空房招租中", IF(ISNUMBER(SEARCH("分層", E23)), IF(COUNTIFS(N:N, N23, O:O, "<>空房招租中") > 0, "入住中", "空房招租中"), IF(COUNTIFS(N:N, N23, O:O, "<>空房招租中", E:E, "*分層*") > 0, "入住中", IF(COUNTIFS(N:N, N23, O:O, "空房招租中", E:E, "*分層*") > 0, "分層優先(隱藏)", "空房招租中") ) ) ) ) -> 入住中 | L23: =IF(AND(A23="", C23="", D23=""), "Z", "A") -> A | O23: =IF(AND(C23<>"", D23<>""), IF(COUNTIFS(sublease_contract!$C:$C, C23, sublease_contract!$D:$D, "*" & D23 & "*", sublease_contract!$G:$G, "<>已退租") = 0, "空房招租中", IF(COUNTIFS(sublease_contract!$C:$C, C23, sublease_contract!$D:$D, "*" & D23 & "*", sublease_contract!$G:$G, "<>已退租", sublease_contract!$N:$N, ">" & (TODAY()+20)) > 0, "入住中", IF(COUNTIFS(sublease_contract!$C:$C, C23, sublease_contract!$D:$D, "*" & D23 & "*", sublease_contract!$G:$G, "<>已退租", sublease_contract!$N:$N, ">=" & TODAY(), sublease_contract!$N:$N, "<=" & (TODAY()+20)) > 0, MINIFS(sublease_contract!$N:$N, sublease_contract!$C:$C, C23, sublease_contract!$D:$D, "*" & D23 & "*", sublease_contract!$G:$G, "<>已退租", sublease_contract!$N:$N, ">=" & TODAY(), sublease_contract!$N:$N, "<=" & (TODAY()+20)), "入住中"))), "") -> 入住中
A24: {=IFERROR( INDEX(big_rental_contract!A:A, MATCH(C24, big_rental_contract!F:F, 0)), "" )} -> A0005 | B24: RL00028 | C24: 北醫醫師府 | D24: C | E24: 分租雅房 | F24: 無 | G24: 9.12 | H24: 13000 | I24: =IF(O24<>"空房招租中", O24, IF(N24="", "空房招租中", IF(ISNUMBER(SEARCH("分層", E24)), IF(COUNTIFS(N:N, N24, O:O, "<>空房招租中") > 0, "入住中", "空房招租中"), IF(COUNTIFS(N:N, N24, O:O, "<>空房招租中", E:E, "*分層*") > 0, "入住中", IF(COUNTIFS(N:N, N24, O:O, "空房招租中", E:E, "*分層*") > 0, "分層優先(隱藏)", "空房招租中") ) ) ) ) -> 入住中 | L24: =IF(AND(A24="", C24="", D24=""), "Z", "A") -> A | O24: =IF(AND(C24<>"", D24<>""), IF(COUNTIFS(sublease_contract!$C:$C, C24, sublease_contract!$D:$D, "*" & D24 & "*", sublease_contract!$G:$G, "<>已退租") = 0, "空房招租中", IF(COUNTIFS(sublease_contract!$C:$C, C24, sublease_contract!$D:$D, "*" & D24 & "*", sublease_contract!$G:$G, "<>已退租", sublease_contract!$N:$N, ">" & (TODAY()+20)) > 0, "入住中", IF(COUNTIFS(sublease_contract!$C:$C, C24, sublease_contract!$D:$D, "*" & D24 & "*", sublease_contract!$G:$G, "<>已退租", sublease_contract!$N:$N, ">=" & TODAY(), sublease_contract!$N:$N, "<=" & (TODAY()+20)) > 0, MINIFS(sublease_contract!$N:$N, sublease_contract!$C:$C, C24, sublease_contract!$D:$D, "*" & D24 & "*", sublease_contract!$G:$G, "<>已退租", sublease_contract!$N:$N, ">=" & TODAY(), sublease_contract!$N:$N, "<=" & (TODAY()+20)), "入住中"))), "") -> 入住中
A25: {=IFERROR( INDEX(big_rental_contract!A:A, MATCH(C25, big_rental_contract!F:F, 0)), "" )} -> A0005 | B25: RL00029 | C25: 北醫醫師府 | D25: D | E25: 分租雅房 | F25: 無 | G25: 7.75 | H25: 12500 | I25: =IF(O25<>"空房招租中", O25, IF(N25="", "空房招租中", IF(ISNUMBER(SEARCH("分層", E25)), IF(COUNTIFS(N:N, N25, O:O, "<>空房招租中") > 0, "入住中", "空房招租中"), IF(COUNTIFS(N:N, N25, O:O, "<>空房招租中", E:E, "*分層*") > 0, "入住中", IF(COUNTIFS(N:N, N25, O:O, "空房招租中", E:E, "*分層*") > 0, "分層優先(隱藏)", "空房招租中") ) ) ) ) -> 入住中 | L25: =IF(AND(A25="", C25="", D25=""), "Z", "A") -> A | O25: =IF(AND(C25<>"", D25<>""), IF(COUNTIFS(sublease_contract!$C:$C, C25, sublease_contract!$D:$D, "*" & D25 & "*", sublease_contract!$G:$G, "<>已退租") = 0, "空房招租中", IF(COUNTIFS(sublease_contract!$C:$C, C25, sublease_contract!$D:$D, "*" & D25 & "*", sublease_contract!$G:$G, "<>已退租", sublease_contract!$N:$N, ">" & (TODAY()+20)) > 0, "入住中", IF(COUNTIFS(sublease_contract!$C:$C, C25, sublease_contract!$D:$D, "*" & D25 & "*", sublease_contract!$G:$G, "<>已退租", sublease_contract!$N:$N, ">=" & TODAY(), sublease_contract!$N:$N, "<=" & (TODAY()+20)) > 0, MINIFS(sublease_contract!$N:$N, sublease_contract!$C:$C, C25, sublease_contract!$D:$D, "*" & D25 & "*", sublease_contract!$G:$G, "<>已退租", sublease_contract!$N:$N, ">=" & TODAY(), sublease_contract!$N:$N, "<=" & (TODAY()+20)), "入住中"))), "") -> 入住中
A26: {=IFERROR( INDEX(big_rental_contract!A:A, MATCH(C26, big_rental_contract!F:F, 0)), "" )} -> A0005 | B26: RL00030 | C26: 北醫醫師府 | D26: E | E26: 分租雅房 | F26: 頂加 | G26: 13.35 | H26: 14800 | I26: =IF(O26<>"空房招租中", O26, IF(N26="", "空房招租中", IF(ISNUMBER(SEARCH("分層", E26)), IF(COUNTIFS(N:N, N26, O:O, "<>空房招租中") > 0, "入住中", "空房招租中"), IF(COUNTIFS(N:N, N26, O:O, "<>空房招租中", E:E, "*分層*") > 0, "入住中", IF(COUNTIFS(N:N, N26, O:O, "空房招租中", E:E, "*分層*") > 0, "分層優先(隱藏)", "空房招租中") ) ) ) ) -> 入住中 | J26: 落地窗大採光超多收納雅房 | K26: https://youtu.be/OQCdRPBv1HU | L26: =IF(AND(A26="", C26="", D26=""), "Z", "A") -> A | M26: 無 | N26: Group_Top_01 | O26: =IF(AND(C26<>"", D26<>""), IF(COUNTIFS(sublease_contract!$C:$C, C26, sublease_contract!$D:$D, "*" & D26 & "*", sublease_contract!$G:$G, "<>已退租") = 0, "空房招租中", IF(COUNTIFS(sublease_contract!$C:$C, C26, sublease_contract!$D:$D, "*" & D26 & "*", sublease_contract!$G:$G, "<>已退租", sublease_contract!$N:$N, ">" & (TODAY()+20)) > 0, "入住中", IF(COUNTIFS(sublease_contract!$C:$C, C26, sublease_contract!$D:$D, "*" & D26 & "*", sublease_contract!$G:$G, "<>已退租", sublease_contract!$N:$N, ">=" & TODAY(), sublease_contract!$N:$N, "<=" & (TODAY()+20)) > 0, MINIFS(sublease_contract!$N:$N, sublease_contract!$C:$C, C26, sublease_contract!$D:$D, "*" & D26 & "*", sublease_contract!$G:$G, "<>已退租", sublease_contract!$N:$N, ">=" & TODAY(), sublease_contract!$N:$N, "<=" & (TODAY()+20)), "入住中"))), "") -> 入住中
A27: {=IFERROR( INDEX(big_rental_contract!A:A, MATCH(C27, big_rental_contract!F:F, 0)), "" )} -> A0005 | B27: RL00031 | C27: 北醫醫師府 | D27: F | E27: 分租雅房 | F27: 頂加 | G27: 14.25 | H27: 14800 | I27: =IF(O27<>"空房招租中", O27, IF(N27="", "空房招租中", IF(ISNUMBER(SEARCH("分層", E27)), IF(COUNTIFS(N:N, N27, O:O, "<>空房招租中") > 0, "入住中", "空房招租中"), IF(COUNTIFS(N:N, N27, O:O, "<>空房招租中", E:E, "*分層*") > 0, "入住中", IF(COUNTIFS(N:N, N27, O:O, "空房招租中", E:E, "*分層*") > 0, "分層優先(隱藏)", "空房招租中") ) ) ) ) -> 入住中 | J27: 雙面採光開窗賞101夜景雅房F | K27: https://youtu.be/0Mv8x7Ghvjs | L27: =IF(AND(A27="", C27="", D27=""), "Z", "A") -> A | M27: 無 | N27: Group_Top_01 | O27: =IF(AND(C27<>"", D27<>""), IF(COUNTIFS(sublease_contract!$C:$C, C27, sublease_contract!$D:$D, "*" & D27 & "*", sublease_contract!$G:$G, "<>已退租") = 0, "空房招租中", IF(COUNTIFS(sublease_contract!$C:$C, C27, sublease_contract!$D:$D, "*" & D27 & "*", sublease_contract!$G:$G, "<>已退租", sublease_contract!$N:$N, ">" & (TODAY()+20)) > 0, "入住中", IF(COUNTIFS(sublease_contract!$C:$C, C27, sublease_contract!$D:$D, "*" & D27 & "*", sublease_contract!$G:$G, "<>已退租", sublease_contract!$N:$N, ">=" & TODAY(), sublease_contract!$N:$N, "<=" & (TODAY()+20)) > 0, MINIFS(sublease_contract!$N:$N, sublease_contract!$C:$C, C27, sublease_contract!$D:$D, "*" & D27 & "*", sublease_contract!$G:$G, "<>已退租", sublease_contract!$N:$N, ">=" & TODAY(), sublease_contract!$N:$N, "<=" & (TODAY()+20)), "入住中"))), "") -> 入住中
A28: {=IFERROR( INDEX(big_rental_contract!A:A, MATCH(C28, big_rental_contract!F:F, 0)), "" )} -> A0006 | B28: RL00032 | C28: 大湖山莊 | D28: A | E28: 分租雅房 | F28: 無 | G28: 10.13 | H28: 13000 | I28: =IF(O28<>"空房招租中", O28, IF(N28="", "空房招租中", IF(ISNUMBER(SEARCH("分層", E28)), IF(COUNTIFS(N:N, N28, O:O, "<>空房招租中") > 0, "入住中", "空房招租中"), IF(COUNTIFS(N:N, N28, O:O, "<>空房招租中", E:E, "*分層*") > 0, "入住中", IF(COUNTIFS(N:N, N28, O:O, "空房招租中", E:E, "*分層*") > 0, "分層優先(隱藏)", "空房招租中") ) ) ) ) -> 入住中 | J28: 挑高3米通風大雅房 | K28: https://www.youtube.com/shorts/BVANUELortA | L28: =IF(AND(A28="", C28="", D28=""), "Z", "A") -> A | O28: =IF(AND(C28<>"", D28<>""), IF(COUNTIFS(sublease_contract!$C:$C, C28, sublease_contract!$D:$D, "*" & D28 & "*", sublease_contract!$G:$G, "<>已退租") = 0, "空房招租中", IF(COUNTIFS(sublease_contract!$C:$C, C28, sublease_contract!$D:$D, "*" & D28 & "*", sublease_contract!$G:$G, "<>已退租", sublease_contract!$N:$N, ">" & (TODAY()+20)) > 0, "入住中", IF(COUNTIFS(sublease_contract!$C:$C, C28, sublease_contract!$D:$D, "*" & D28 & "*", sublease_contract!$G:$G, "<>已退租", sublease_contract!$N:$N, ">=" & TODAY(), sublease_contract!$N:$N, "<=" & (TODAY()+20)) > 0, MINIFS(sublease_contract!$N:$N, sublease_contract!$C:$C, C28, sublease_contract!$D:$D, "*" & D28 & "*", sublease_contract!$G:$G, "<>已退租", sublease_contract!$N:$N, ">=" & TODAY(), sublease_contract!$N:$N, "<=" & (TODAY()+20)), "入住中"))), "") -> 入住中
A29: {=IFERROR( INDEX(big_rental_contract!A:A, MATCH(C29, big_rental_contract!F:F, 0)), "" )} -> A0006 | B29: RL00033 | C29: 大湖山莊 | D29: B | E29: 分租雅房 | F29: 無 | G29: 8.94 | H29: 12000 | I29: =IF(O29<>"空房招租中", O29, IF(N29="", "空房招租中", IF(ISNUMBER(SEARCH("分層", E29)), IF(COUNTIFS(N:N, N29, O:O, "<>空房招租中") > 0, "入住中", "空房招租中"), IF(COUNTIFS(N:N, N29, O:O, "<>空房招租中", E:E, "*分層*") > 0, "入住中", IF(COUNTIFS(N:N, N29, O:O, "空房招租中", E:E, "*分層*") > 0, "分層優先(隱藏)", "空房招租中") ) ) ) ) -> 入住中 | J29: 方正實心牆典雅雅房 | K29: https://youtube.com/shorts/Fvij9jinV0I?si=tbMFzPki-t7Xte74 | L29: =IF(AND(A29="", C29="", D29=""), "Z", "A") -> A | O29: =IF(AND(C29<>"", D29<>""), IF(COUNTIFS(sublease_contract!$C:$C, C29, sublease_contract!$D:$D, "*" & D29 & "*", sublease_contract!$G:$G, "<>已退租") = 0, "空房招租中", IF(COUNTIFS(sublease_contract!$C:$C, C29, sublease_contract!$D:$D, "*" & D29 & "*", sublease_contract!$G:$G, "<>已退租", sublease_contract!$N:$N, ">" & (TODAY()+20)) > 0, "入住中", IF(COUNTIFS(sublease_contract!$C:$C, C29, sublease_contract!$D:$D, "*" & D29 & "*", sublease_contract!$G:$G, "<>已退租", sublease_contract!$N:$N, ">=" & TODAY(), sublease_contract!$N:$N, "<=" & (TODAY()+20)) > 0, MINIFS(sublease_contract!$N:$N, sublease_contract!$C:$C, C29, sublease_contract!$D:$D, "*" & D29 & "*", sublease_contract!$G:$G, "<>已退租", sublease_contract!$N:$N, ">=" & TODAY(), sublease_contract!$N:$N, "<=" & (TODAY()+20)), "入住中"))), "") -> 入住中
A30: {=IFERROR( INDEX(big_rental_contract!A:A, MATCH(C30, big_rental_contract!F:F, 0)), "" )} -> A0006 | B30: RL00034 | C30: 大湖山莊 | D30: C | E30: 分租套房 | F30: 無 | G30: 26.72 | H30: 20800 | I30: =IF(O30<>"空房招租中", O30, IF(N30="", "空房招租中", IF(ISNUMBER(SEARCH("分層", E30)), IF(COUNTIFS(N:N, N30, O:O, "<>空房招租中") > 0, "入住中", "空房招租中"), IF(COUNTIFS(N:N, N30, O:O, "<>空房招租中", E:E, "*分層*") > 0, "入住中", IF(COUNTIFS(N:N, N30, O:O, "空房招租中", E:E, "*分層*") > 0, "分層優先(隱藏)", "空房招租中") ) ) ) ) -> 入住中 | J30: 獨立陽台獨立洗衣機大套房 | L30: =IF(AND(A30="", C30="", D30=""), "Z", "A") -> A | O30: =IF(AND(C30<>"", D30<>""), IF(COUNTIFS(sublease_contract!$C:$C, C30, sublease_contract!$D:$D, "*" & D30 & "*", sublease_contract!$G:$G, "<>已退租") = 0, "空房招租中", IF(COUNTIFS(sublease_contract!$C:$C, C30, sublease_contract!$D:$D, "*" & D30 & "*", sublease_contract!$G:$G, "<>已退租", sublease_contract!$N:$N, ">" & (TODAY()+20)) > 0, "入住中", IF(COUNTIFS(sublease_contract!$C:$C, C30, sublease_contract!$D:$D, "*" & D30 & "*", sublease_contract!$G:$G, "<>已退租", sublease_contract!$N:$N, ">=" & TODAY(), sublease_contract!$N:$N, "<=" & (TODAY()+20)) > 0, MINIFS(sublease_contract!$N:$N, sublease_contract!$C:$C, C30, sublease_contract!$D:$D, "*" & D30 & "*", sublease_contract!$G:$G, "<>已退租", sublease_contract!$N:$N, ">=" & TODAY(), sublease_contract!$N:$N, "<=" & (TODAY()+20)), "入住中"))), "") -> 入住中
A31: {=IFERROR( INDEX(big_rental_contract!A:A, MATCH(C31, big_rental_contract!F:F, 0)), "" )} -> A0006 | B31: RL00035 | C31: 大湖山莊 | D31: D | E31: 分租雅房 | F31: 無 | G31: 14.7 | H31: 14800 | I31: =IF(O31<>"空房招租中", O31, IF(N31="", "空房招租中", IF(ISNUMBER(SEARCH("分層", E31)), IF(COUNTIFS(N:N, N31, O:O, "<>空房招租中") > 0, "入住中", "空房招租中"), IF(COUNTIFS(N:N, N31, O:O, "<>空房招租中", E:E, "*分層*") > 0, "入住中", IF(COUNTIFS(N:N, N31, O:O, "空房招租中", E:E, "*分層*") > 0, "分層優先(隱藏)", "空房招租中") ) ) ) ) -> 入住中 | J31: 四櫃收納瑜珈人大雅房 | L31: =IF(AND(A31="", C31="", D31=""), "Z", "A") -> A | O31: =IF(AND(C31<>"", D31<>""), IF(COUNTIFS(sublease_contract!$C:$C, C31, sublease_contract!$D:$D, "*" & D31 & "*", sublease_contract!$G:$G, "<>已退租") = 0, "空房招租中", IF(COUNTIFS(sublease_contract!$C:$C, C31, sublease_contract!$D:$D, "*" & D31 & "*", sublease_contract!$G:$G, "<>已退租", sublease_contract!$N:$N, ">" & (TODAY()+20)) > 0, "入住中", IF(COUNTIFS(sublease_contract!$C:$C, C31, sublease_contract!$D:$D, "*" & D31 & "*", sublease_contract!$G:$G, "<>已退租", sublease_contract!$N:$N, ">=" & TODAY(), sublease_contract!$N:$N, "<=" & (TODAY()+20)) > 0, MINIFS(sublease_contract!$N:$N, sublease_contract!$C:$C, C31, sublease_contract!$D:$D, "*" & D31 & "*", sublease_contract!$G:$G, "<>已退租", sublease_contract!$N:$N, ">=" & TODAY(), sublease_contract!$N:$N, "<=" & (TODAY()+20)), "入住中"))), "") -> 入住中
A32: {=IFERROR( INDEX(big_rental_contract!A:A, MATCH(C32, big_rental_contract!F:F, 0)), "" )} -> A0006 | B32: RL00036 | C32: 大湖山莊 | D32: E | E32: 分租雅房 | F32: 無 | G32: 9.2 | H32: 12500 | I32: =IF(O32<>"空房招租中", O32, IF(N32="", "空房招租中", IF(ISNUMBER(SEARCH("分層", E32)), IF(COUNTIFS(N:N, N32, O:O, "<>空房招租中") > 0, "入住中", "空房招租中"), IF(COUNTIFS(N:N, N32, O:O, "<>空房招租中", E:E, "*分層*") > 0, "入住中", IF(COUNTIFS(N:N, N32, O:O, "空房招租中", E:E, "*分層*") > 0, "分層優先(隱藏)", "空房招租中") ) ) ) ) -> 入住中 | J32: 有標準門的和式清幽雅房 | L32: =IF(AND(A32="", C32="", D32=""), "Z", "A") -> A | O32: =IF(AND(C32<>"", D32<>""), IF(COUNTIFS(sublease_contract!$C:$C, C32, sublease_contract!$D:$D, "*" & D32 & "*", sublease_contract!$G:$G, "<>已退租") = 0, "空房招租中", IF(COUNTIFS(sublease_contract!$C:$C, C32, sublease_contract!$D:$D, "*" & D32 & "*", sublease_contract!$G:$G, "<>已退租", sublease_contract!$N:$N, ">" & (TODAY()+20)) > 0, "入住中", IF(COUNTIFS(sublease_contract!$C:$C, C32, sublease_contract!$D:$D, "*" & D32 & "*", sublease_contract!$G:$G, "<>已退租", sublease_contract!$N:$N, ">=" & TODAY(), sublease_contract!$N:$N, "<=" & (TODAY()+20)) > 0, MINIFS(sublease_contract!$N:$N, sublease_contract!$C:$C, C32, sublease_contract!$D:$D, "*" & D32 & "*", sublease_contract!$G:$G, "<>已退租", sublease_contract!$N:$N, ">=" & TODAY(), sublease_contract!$N:$N, "<=" & (TODAY()+20)), "入住中"))), "") -> 入住中
A33: {=IFERROR( INDEX(big_rental_contract!A:A, MATCH(C33, big_rental_contract!F:F, 0)), "" )} -> A0006 | B33: RL00037 | C33: 大湖山莊 | D33: F | E33: 分租雅房 | F33: 頂加 | G33: 22.3 | H33: 17800 | I33: =IF(O33<>"空房招租中", O33, IF(N33="", "空房招租中", IF(ISNUMBER(SEARCH("分層", E33)), IF(COUNTIFS(N:N, N33, O:O, "<>空房招租中") > 0, "入住中", "空房招租中"), IF(COUNTIFS(N:N, N33, O:O, "<>空房招租中", E:E, "*分層*") > 0, "入住中", IF(COUNTIFS(N:N, N33, O:O, "空房招租中", E:E, "*分層*") > 0, "分層優先(隱藏)", "空房招租中") ) ) ) ) -> 入住中 | J33: 大空間超多收納一房一廳頂加採光雅房 | K33: https://youtu.be/X1mOO7o74Uk | L33: =IF(AND(A33="", C33="", D33=""), "Z", "A") -> A | O33: =IF(AND(C33<>"", D33<>""), IF(COUNTIFS(sublease_contract!$C:$C, C33, sublease_contract!$D:$D, "*" & D33 & "*", sublease_contract!$G:$G, "<>已退租") = 0, "空房招租中", IF(COUNTIFS(sublease_contract!$C:$C, C33, sublease_contract!$D:$D, "*" & D33 & "*", sublease_contract!$G:$G, "<>已退租", sublease_contract!$N:$N, ">" & (TODAY()+20)) > 0, "入住中", IF(COUNTIFS(sublease_contract!$C:$C, C33, sublease_contract!$D:$D, "*" & D33 & "*", sublease_contract!$G:$G, "<>已退租", sublease_contract!$N:$N, ">=" & TODAY(), sublease_contract!$N:$N, "<=" & (TODAY()+20)) > 0, MINIFS(sublease_contract!$N:$N, sublease_contract!$C:$C, C33, sublease_contract!$D:$D, "*" & D33 & "*", sublease_contract!$G:$G, "<>已退租", sublease_contract!$N:$N, ">=" & TODAY(), sublease_contract!$N:$N, "<=" & (TODAY()+20)), "入住中"))), "") -> 入住中
A34: {=IFERROR( INDEX(big_rental_contract!A:A, MATCH(C34, big_rental_contract!F:F, 0)), "" )} -> A0006 | B34: RL00038 | C34: 大湖山莊 | D34: G | E34: 分租雅房 | F34: 頂加 | G34: 12.96 | H34: 15800 | I34: =IF(O34<>"空房招租中", O34, IF(N34="", "空房招租中", IF(ISNUMBER(SEARCH("分層", E34)), IF(COUNTIFS(N:N, N34, O:O, "<>空房招租中") > 0, "入住中", "空房招租中"), IF(COUNTIFS(N:N, N34, O:O, "<>空房招租中", E:E, "*分層*") > 0, "入住中", IF(COUNTIFS(N:N, N34, O:O, "空房招租中", E:E, "*分層*") > 0, "分層優先(隱藏)", "空房招租中") ) ) ) ) -> 入住中 | J34: 大片採光 獨立陽台 獨立洗衣機 頂加雅房 | K34: https://www.youtube.com/shorts/H7Gx0qFtcmI | L34: =IF(AND(A34="", C34="", D34=""), "Z", "A") -> A | O34: =IF(AND(C34<>"", D34<>""), IF(COUNTIFS(sublease_contract!$C:$C, C34, sublease_contract!$D:$D, "*" & D34 & "*", sublease_contract!$G:$G, "<>已退租") = 0, "空房招租中", IF(COUNTIFS(sublease_contract!$C:$C, C34, sublease_contract!$D:$D, "*" & D34 & "*", sublease_contract!$G:$G, "<>已退租", sublease_contract!$N:$N, ">" & (TODAY()+20)) > 0, "入住中", IF(COUNTIFS(sublease_contract!$C:$C, C34, sublease_contract!$D:$D, "*" & D34 & "*", sublease_contract!$G:$G, "<>已退租", sublease_contract!$N:$N, ">=" & TODAY(), sublease_contract!$N:$N, "<=" & (TODAY()+20)) > 0, MINIFS(sublease_contract!$N:$N, sublease_contract!$C:$C, C34, sublease_contract!$D:$D, "*" & D34 & "*", sublease_contract!$G:$G, "<>已退租", sublease_contract!$N:$N, ">=" & TODAY(), sublease_contract!$N:$N, "<=" & (TODAY()+20)), "入住中"))), "") -> 入住中
A35: {=IFERROR( INDEX(big_rental_contract!A:A, MATCH(C35, big_rental_contract!F:F, 0)), "" )} -> A0007 | B35: RL00013 | C35: 士林和豐 | D35: A | E35: 分租套房 | F35: 無 | G35: 20.95 | H35: 19500 | I35: =IF(O35<>"空房招租中", O35, IF(N35="", "空房招租中", IF(ISNUMBER(SEARCH("分層", E35)), IF(COUNTIFS(N:N, N35, O:O, "<>空房招租中") > 0, "入住中", "空房招租中"), IF(COUNTIFS(N:N, N35, O:O, "<>空房招租中", E:E, "*分層*") > 0, "入住中", IF(COUNTIFS(N:N, N35, O:O, "空房招租中", E:E, "*分層*") > 0, "分層優先(隱藏)", "空房招租中") ) ) ) ) -> 入住中 | L35: =IF(AND(A35="", C35="", D35=""), "Z", "A") -> A | O35: =IF(AND(C35<>"", D35<>""), IF(COUNTIFS(sublease_contract!$C:$C, C35, sublease_contract!$D:$D, "*" & D35 & "*", sublease_contract!$G:$G, "<>已退租") = 0, "空房招租中", IF(COUNTIFS(sublease_contract!$C:$C, C35, sublease_contract!$D:$D, "*" & D35 & "*", sublease_contract!$G:$G, "<>已退租", sublease_contract!$N:$N, ">" & (TODAY()+20)) > 0, "入住中", IF(COUNTIFS(sublease_contract!$C:$C, C35, sublease_contract!$D:$D, "*" & D35 & "*", sublease_contract!$G:$G, "<>已退租", sublease_contract!$N:$N, ">=" & TODAY(), sublease_contract!$N:$N, "<=" & (TODAY()+20)) > 0, MINIFS(sublease_contract!$N:$N, sublease_contract!$C:$C, C35, sublease_contract!$D:$D, "*" & D35 & "*", sublease_contract!$G:$G, "<>已退租", sublease_contract!$N:$N, ">=" & TODAY(), sublease_contract!$N:$N, "<=" & (TODAY()+20)), "入住中"))), "") -> 入住中
A36: {=IFERROR( INDEX(big_rental_contract!A:A, MATCH(C36, big_rental_contract!F:F, 0)), "" )} -> A0007 | B36: RL00014 | C36: 士林和豐 | D36: B | E36: 分租雅房 | F36: 無 | G36: 10.34 | H36: 13500 | I36: =IF(O36<>"空房招租中", O36, IF(N36="", "空房招租中", IF(ISNUMBER(SEARCH("分層", E36)), IF(COUNTIFS(N:N, N36, O:O, "<>空房招租中") > 0, "入住中", "空房招租中"), IF(COUNTIFS(N:N, N36, O:O, "<>空房招租中", E:E, "*分層*") > 0, "入住中", IF(COUNTIFS(N:N, N36, O:O, "空房招租中", E:E, "*分層*") > 0, "分層優先(隱藏)", "空房招租中") ) ) ) ) -> 入住中 | J36: 獨立陽台大採光雅房 | K36: https://youtube.com/shorts/w4m3C_SQfU0?si=AG4_Bc2RFth2LSdH | L36: =IF(AND(A36="", C36="", D36=""), "Z", "A") -> A | O36: =IF(AND(C36<>"", D36<>""), IF(COUNTIFS(sublease_contract!$C:$C, C36, sublease_contract!$D:$D, "*" & D36 & "*", sublease_contract!$G:$G, "<>已退租") = 0, "空房招租中", IF(COUNTIFS(sublease_contract!$C:$C, C36, sublease_contract!$D:$D, "*" & D36 & "*", sublease_contract!$G:$G, "<>已退租", sublease_contract!$N:$N, ">" & (TODAY()+20)) > 0, "入住中", IF(COUNTIFS(sublease_contract!$C:$C, C36, sublease_contract!$D:$D, "*" & D36 & "*", sublease_contract!$G:$G, "<>已退租", sublease_contract!$N:$N, ">=" & TODAY(), sublease_contract!$N:$N, "<=" & (TODAY()+20)) > 0, MINIFS(sublease_contract!$N:$N, sublease_contract!$C:$C, C36, sublease_contract!$D:$D, "*" & D36 & "*", sublease_contract!$G:$G, "<>已退租", sublease_contract!$N:$N, ">=" & TODAY(), sublease_contract!$N:$N, "<=" & (TODAY()+20)), "入住中"))), "") -> 入住中
A37: {=IFERROR( INDEX(big_rental_contract!A:A, MATCH(C37, big_rental_contract!F:F, 0)), "" )} -> A0007 | B37: RL00015 | C37: 士林和豐 | D37: C | E37: 分租雅房 | F37: 無 | G37: 11.92 | H37: 13000 | I37: =IF(O37<>"空房招租中", O37, IF(N37="", "空房招租中", IF(ISNUMBER(SEARCH("分層", E37)), IF(COUNTIFS(N:N, N37, O:O, "<>空房招租中") > 0, "入住中", "空房招租中"), IF(COUNTIFS(N:N, N37, O:O, "<>空房招租中", E:E, "*分層*") > 0, "入住中", IF(COUNTIFS(N:N, N37, O:O, "空房招租中", E:E, "*分層*") > 0, "分層優先(隱藏)", "空房招租中") ) ) ) ) -> 入住中 | J37: 方正全實心牆雅房 | K37: https://youtube.com/shorts/f59bfvV6lkw?si=X-Lx2UbnA76uz6Ac | L37: =IF(AND(A37="", C37="", D37=""), "Z", "A") -> A | O37: =IF(AND(C37<>"", D37<>""), IF(COUNTIFS(sublease_contract!$C:$C, C37, sublease_contract!$D:$D, "*" & D37 & "*", sublease_contract!$G:$G, "<>已退租") = 0, "空房招租中", IF(COUNTIFS(sublease_contract!$C:$C, C37, sublease_contract!$D:$D, "*" & D37 & "*", sublease_contract!$G:$G, "<>已退租", sublease_contract!$N:$N, ">" & (TODAY()+20)) > 0, "入住中", IF(COUNTIFS(sublease_contract!$C:$C, C37, sublease_contract!$D:$D, "*" & D37 & "*", sublease_contract!$G:$G, "<>已退租", sublease_contract!$N:$N, ">=" & TODAY(), sublease_contract!$N:$N, "<=" & (TODAY()+20)) > 0, MINIFS(sublease_contract!$N:$N, sublease_contract!$C:$C, C37, sublease_contract!$D:$D, "*" & D37 & "*", sublease_contract!$G:$G, "<>已退租", sublease_contract!$N:$N, ">=" & TODAY(), sublease_contract!$N:$N, "<=" & (TODAY()+20)), "入住中"))), "") -> 入住中
A38: {=IFERROR( INDEX(big_rental_contract!A:A, MATCH(C38, big_rental_contract!F:F, 0)), "" )} -> A0007 | B38: RL00016 | C38: 士林和豐 | D38: D | E38: 分租雅房 | F38: 無 | G38: 10.91 | H38: 12500 | I38: =IF(O38<>"空房招租中", O38, IF(N38="", "空房招租中", IF(ISNUMBER(SEARCH("分層", E38)), IF(COUNTIFS(N:N, N38, O:O, "<>空房招租中") > 0, "入住中", "空房招租中"), IF(COUNTIFS(N:N, N38, O:O, "<>空房招租中", E:E, "*分層*") > 0, "入住中", IF(COUNTIFS(N:N, N38, O:O, "空房招租中", E:E, "*分層*") > 0, "分層優先(隱藏)", "空房招租中") ) ) ) ) -> 入住中 | L38: =IF(AND(A38="", C38="", D38=""), "Z", "A") -> A | O38: =IF(AND(C38<>"", D38<>""), IF(COUNTIFS(sublease_contract!$C:$C, C38, sublease_contract!$D:$D, "*" & D38 & "*", sublease_contract!$G:$G, "<>已退租") = 0, "空房招租中", IF(COUNTIFS(sublease_contract!$C:$C, C38, sublease_contract!$D:$D, "*" & D38 & "*", sublease_contract!$G:$G, "<>已退租", sublease_contract!$N:$N, ">" & (TODAY()+20)) > 0, "入住中", IF(COUNTIFS(sublease_contract!$C:$C, C38, sublease_contract!$D:$D, "*" & D38 & "*", sublease_contract!$G:$G, "<>已退租", sublease_contract!$N:$N, ">=" & TODAY(), sublease_contract!$N:$N, "<=" & (TODAY()+20)) > 0, MINIFS(sublease_contract!$N:$N, sublease_contract!$C:$C, C38, sublease_contract!$D:$D, "*" & D38 & "*", sublease_contract!$G:$G, "<>已退租", sublease_contract!$N:$N, ">=" & TODAY(), sublease_contract!$N:$N, "<=" & (TODAY()+20)), "入住中"))), "") -> 入住中
A39: {=IFERROR( INDEX(big_rental_contract!A:A, MATCH(C39, big_rental_contract!F:F, 0)), "" )} -> A0008 | B39: RL00040 | C39: 南港站挑高宅 | D39: A | E39: 分租雅房 | F39: 無 | G39: 8.48 | H39: 13000 | I39: =IF(O39<>"空房招租中", O39, IF(N39="", "空房招租中", IF(ISNUMBER(SEARCH("分層", E39)), IF(COUNTIFS(N:N, N39, O:O, "<>空房招租中") > 0, "入住中", "空房招租中"), IF(COUNTIFS(N:N, N39, O:O, "<>空房招租中", E:E, "*分層*") > 0, "入住中", IF(COUNTIFS(N:N, N39, O:O, "空房招租中", E:E, "*分層*") > 0, "分層優先(隱藏)", "空房招租中") ) ) ) ) -> 入住中 | L39: =IF(AND(A39="", C39="", D39=""), "Z", "A") -> A | O39: =IF(AND(C39<>"", D39<>""), IF(COUNTIFS(sublease_contract!$C:$C, C39, sublease_contract!$D:$D, "*" & D39 & "*", sublease_contract!$G:$G, "<>已退租") = 0, "空房招租中", IF(COUNTIFS(sublease_contract!$C:$C, C39, sublease_contract!$D:$D, "*" & D39 & "*", sublease_contract!$G:$G, "<>已退租", sublease_contract!$N:$N, ">" & (TODAY()+20)) > 0, "入住中", IF(COUNTIFS(sublease_contract!$C:$C, C39, sublease_contract!$D:$D, "*" & D39 & "*", sublease_contract!$G:$G, "<>已退租", sublease_contract!$N:$N, ">=" & TODAY(), sublease_contract!$N:$N, "<=" & (TODAY()+20)) > 0, MINIFS(sublease_contract!$N:$N, sublease_contract!$C:$C, C39, sublease_contract!$D:$D, "*" & D39 & "*", sublease_contract!$G:$G, "<>已退租", sublease_contract!$N:$N, ">=" & TODAY(), sublease_contract!$N:$N, "<=" & (TODAY()+20)), "入住中"))), "") -> 入住中
A40: {=IFERROR( INDEX(big_rental_contract!A:A, MATCH(C40, big_rental_contract!F:F, 0)), "" )} -> A0008 | B40: RL00041 | C40: 南港站挑高宅 | D40: B | E40: 分租雅房 | F40: 無 | G40: 7.76 | H40: 11500 | I40: =IF(O40<>"空房招租中", O40, IF(N40="", "空房招租中", IF(ISNUMBER(SEARCH("分層", E40)), IF(COUNTIFS(N:N, N40, O:O, "<>空房招租中") > 0, "入住中", "空房招租中"), IF(COUNTIFS(N:N, N40, O:O, "<>空房招租中", E:E, "*分層*") > 0, "入住中", IF(COUNTIFS(N:N, N40, O:O, "空房招租中", E:E, "*分層*") > 0, "分層優先(隱藏)", "空房招租中") ) ) ) ) -> 入住中 | K40: https://youtu.be/a5mQVdGrbrU | L40: =IF(AND(A40="", C40="", D40=""), "Z", "A") -> A | O40: =IF(AND(C40<>"", D40<>""), IF(COUNTIFS(sublease_contract!$C:$C, C40, sublease_contract!$D:$D, "*" & D40 & "*", sublease_contract!$G:$G, "<>已退租") = 0, "空房招租中", IF(COUNTIFS(sublease_contract!$C:$C, C40, sublease_contract!$D:$D, "*" & D40 & "*", sublease_contract!$G:$G, "<>已退租", sublease_contract!$N:$N, ">" & (TODAY()+20)) > 0, "入住中", IF(COUNTIFS(sublease_contract!$C:$C, C40, sublease_contract!$D:$D, "*" & D40 & "*", sublease_contract!$G:$G, "<>已退租", sublease_contract!$N:$N, ">=" & TODAY(), sublease_contract!$N:$N, "<=" & (TODAY()+20)) > 0, MINIFS(sublease_contract!$N:$N, sublease_contract!$C:$C, C40, sublease_contract!$D:$D, "*" & D40 & "*", sublease_contract!$G:$G, "<>已退租", sublease_contract!$N:$N, ">=" & TODAY(), sublease_contract!$N:$N, "<=" & (TODAY()+20)), "入住中"))), "") -> 入住中
...

Sheet big_rental_contract
A1: id | B1: tax_reduction_applied | C1: file_archived | D1: auto_transfer | E1: system_registered | F1: property_name | G1: owner_name | H1: monthly_rent | I1: contract_signed_date | J1: contract_start_date | K1: contract_end_date | L1: city | M1: district | N1: address | O1: land_section | P1: land_number | Q1: building_number | R1: building_area_sqm | S1: living_room_count | T1: bathroom_count | U1: bedroom_count | V1: total_floors | W1: rented_floor | X1: rented_floor_cn | Y1: building_type | Z1: owner_id_number | AA1: owner_contact | AB1: remittance_account | AC1: secondary_remittance_account | AD1: contract_signed_date_minguo | AE1: contract_start_date_minguo | AF1: contract_end_date_minguo | AG1: case_number | AH1: phase1_rent_start_date | AI1: phase1_rent_amount | AJ1: phase2_rent_start_date | AK1: phase2_rent_amount | AL1: phase3_rent_start_date | AM1: phase3_rent_amount | AN1: phase4_rent_start_date | AO1: phase4_rent_amount | AP1: next_payment_date_estimated | AQ1: auto_transfer_last_date | AR1: transfer_date | AS1: transfer_amount_estimated | AT1: first_month_amount | AU1: last_payment_date | AV1: last_payment_amount | AW1: notes | AX1: tag | AY1: second_owner_name | AZ1: second_owner_id | BA1: third_owner_name | BB1: third_owner_id | BC1: Description | BD1: 垃圾代收/樓梯清潔/管理費 | BE1: public_area_video | BF1: full_description
A2: A0001 | B2: TRUE | C2: TRUE | D2: TRUE | E2: TRUE | F2: 永春四號 | G2: 郭宗仁 | H2: 34000 | I2: 45212 | J2: 45212 | K2: 48883 | L2: 臺北市 | M2: 信義區 | N2: 忠孝東路五段466號四樓 | O2: 信義段一小段 | P2: 0104-0000 | Q2: 00791000 | R2: 95.4 | S2: 2 | T2: 1 | U2: 4 | V2: 4 | W2: 4 | X2: 四層 | Y2: 公寓(無電梯) | Z2: F122308421 | AA2: 0987249595 | AB2: (012)00620168284509 0000721168746295 | AC2: (012)00721168746295 | AD2: =if(ISBLANK(I2),, YEAR(I2)-1911&TEXT(I2,"mmdd")) -> 1121013 | AE2: =if(ISBLANK(J2),, YEAR(J2)-1911&TEXT(J2,"mmdd")) -> 1121013 | AF2: =if(ISBLANK(K2),, YEAR(K2)-1911&TEXT(K2,"mmdd")) -> 1221031 | AG2: BAA9405318211240143 | AH2: 45212 | AI2: 34000 | AJ2: 46096 | AK2: 54000 | AP2: 台銀在 台幣簡易轉帳 歷史紀錄選用 可以一次"多選"設定 進入草稿後編輯 | AQ2: 2025.06.1 | AR2: 每個月一號給兩個帳戶 | AS2: 17000*2(雙帳號) | AX2: 貓狗企鵝 | AY2: 郭玟君 | AZ2: F228154223 | BC2: 📌租金包含: 網路費 📌押金: 2個月 📌仲介費: 免仲介費 📌租期: 可短租 📌能源費: 水、電、瓦斯依帳單 室友人頭均攤 🚶步行 1分鐘 7-11便利商店 1分鐘 康是美 1分鐘 捷運永春站 2分鐘 虎林街美食、虎林市場 3分鐘 壽司郎 🚲 YouBike 4分鐘ubike到 五分埔 5分鐘ubike到 饒河夜市 | BD2: 無 | BF2: 🚇永春站正樓上🚇, 到站就到家 󠀠 在繁忙的城市生活中，有什麼比每天返家更讓人舒適的呢？我們位於捷運站樓上，意味著當你到達站點，你已經回到了溫馨的家。 󠀠 居家辦公、下班累了想吃美食，6分鐘內的距離絕對不怕沒食物 1分鐘捷運到 信義商圈 2分鐘走路到 虎林街美食、虎林市場 3分鐘走路到 壽司郎 4分鐘ubike到 五分埔 5分鐘ubike到 饒河夜市 󠀠 臨時想買點東西, 10秒內步行即可到達便利商店&康是美. 󠀠 📌地點: 永春站 信義區 忠孝東路五段 四樓 公寓 📌格局: 【房型】公寓2層 4F & 5F → 4F 共生公寓 四房一衛一廳一廚一陽台 → 5F 兩房一衛一廳一廚一陽台 頂加 📌設備: 冷氣、雙人床、衣櫃、40吋以上電視、桌椅、洗衣機、冰箱、瓦斯爐、抽油煙機、熱水器、120M網路&WIFI 📌租金包含: 網路費
A3: A0002 | B3: TRUE | C3: TRUE | D3: TRUE | E3: TRUE | F3: 內湖秘境 | G3: 周佳慧 | H3: 45000 | I3: 45190 | J3: 45190 | K3: 48883 | L3: 臺北市 | M3: 內湖區 | N3: 內湖路一段47巷46號五樓 | O3: 西湖段二小段 | P3: 0439-0000 | Q3: 01432-000 | R3: 103.04 | S3: 1 | T3: 1 | U3: 5 | V3: 5 | W3: 5 | X3: 五層 | Y3: 公寓(無電梯) | Z3: A221172157 | AA3: 02-29671862 | AB3: 012/0000689168153048 700/03116810484843 810/6709177212 | AD3: =if(ISBLANK(I3),, YEAR(I3)-1911&TEXT(I3,"mmdd")) -> 1120921 | AE3: =if(ISBLANK(J3),, YEAR(J3)-1911&TEXT(J3,"mmdd")) -> 1120921 | AF3: =if(ISBLANK(K3),, YEAR(K3)-1911&TEXT(K3,"mmdd")) -> 1221031 | AG3: BAA9405318211231268 | AH3: 45190 | AI3: 45000 | AJ3: 47058 | AK3: 47000 | AO3: 47000 | AQ3: 2025.12.1 | AR3: 每個月1號 | AS3: 15000*3 | AX3: 鯰魚大大 | BC3: =====內 科 綠 樹 景 觀 房===== 與綠蔭共居 適合重視生活品質的你 💲󠀠垃圾代收 💲公共區清潔 💲1G超高速網路 =====歡 迎 申 請 租 金 補 貼===== 󠀠 󠀠 近美麗華 / 內科 / 內湖路一段 / 文湖街󠀠 劍南路站 / 騎車4MIN / 步行12MIN 西湖站 / 騎車5MIN / 步行16MIN 【房型】公寓2層 7雅 2衛 1廚 大露臺󠀠 󠀠 【租金包含】垃圾代收、公共區清潔、1G超高速網路費 【押金】2個月，租期1年起 【能源費】水、電、瓦斯依帳單 室友人頭均攤 【設備】3M生飲濾水器、冷氣、掀床床墊組、衣櫃、書桌椅、洗衣機*2、冰箱*2、餐桌、瓦斯爐、抽油煙機、熱水器、1G 網路 & WIFI 󠀠 󠀠 | BD3: Local廠商 放一樓 | BE3: https://youtu.be/o8CQn0wxxQQ | BF3: =====內 科 綠 樹 景 觀 房===== 󠀠 󠀠 與綠蔭共居 適合重視生活品質的你 💲󠀠垃圾代收 💲公共區清潔 💲1G超高速網路 =====歡 迎 申 請 租 金 補 貼===== 󠀠 󠀠 近美麗華 / 內科 / 內湖路一段 / 文湖街󠀠 劍南路站 / 騎車4MIN / 步行12MIN 西湖站 / 騎車5MIN / 步行16MIN 󠀠󠀠 雖然距離捷運要走一小段，但因為這樣的距離， 換到遠離塵囂的生活品質 󠀠 󠀠 【房型】公寓2層 7雅 2衛 1廚 大露臺 󠀠 󠀠 󠀠 󠀠 【租金包含】垃圾代收、公共區清潔、1G超高速網路費 【設備】3M生飲濾水器、冷氣、掀床床墊組、衣櫃、書桌椅、洗衣機*2、冰箱*2、餐桌、瓦斯爐、抽油煙機、熱水器、1G 網路 & WIFI
A4: A0003 | B4: TRUE | C4: TRUE | D4: TRUE | E4: TRUE | F4: 龍江229 | G4: 游為傑 | H4: 27000 | I4: 45264 | J4: 45264 | K4: 47087 | L4: 臺北市 | M4: 中山區 | N4: 龍江路229巷2之3號三樓 | O4: 長春段一小段 | P4: 0061-0000 | Q4: 01553-000 | R4: 89.42 | S4: 1 | T4: 2 | U4: 5 | V4: 4 | W4: 3 | X4: 三層 | Y4: 公寓(無電梯) | Z4: A124455973 | AA4: 0920488835 | AB4: 700-00021680019509 | AD4: =if(ISBLANK(I4),, YEAR(I4)-1911&TEXT(I4,"mmdd")) -> 1121204 | AE4: =if(ISBLANK(J4),, YEAR(J4)-1911&TEXT(J4,"mmdd")) -> 1121204 | AF4: =if(ISBLANK(K4),, YEAR(K4)-1911&TEXT(K4,"mmdd")) -> 1171130 | AG4: BAA9405318211240558 | AH4: 45264 | AI4: 27000 | AQ4: 2025.06.13 | AR4: 每個月1號 跟 15號 | AS4: 13500*2 | AU4: 47058 | AV4: 22830 | AX4: 貓狗企鵝 | BC4: 📌地點: 中山區 龍江路229巷 3樓 公寓 📌格局: 1廚1廳2陽台2衛浴 (4雅1套) 📌設備: 冷氣、單/雙人床、衣櫃、桌椅、蒸氣洗衣機、冰箱、瓦斯爐、抽油煙機、熱水器、濾水器、120M網路&WIFI 📌租金包含: 網路費、垃圾代收費 📌押金: 2個月 📌租期: 1年起 📌能源費: 水、電、瓦斯依帳單 室友人頭均攤 🚶步行 3分鐘走路到 台北大學 🚲 YouBike 3分鐘 Ubike到 錦州街美食區 3分鐘 Ubike到 中山國中捷運站 3分鐘 Ubike到 南京復興捷運站 4分鐘 Ubike到 行天宮捷運站 4分鐘 Ubike到 遼寧夜市 5分鐘 Ubike到 錢櫃松江 6分鐘 Ubike到 長春國賓影城 | BD4: 垃可 | BE4: https://youtube.com/shorts/p2uw-IupzaE?si=zpNopgBQCQ7OBNQx | BF4: 近台北大學, 寧靜優雅的書香環境. 黃線 綠線 棕線捷運 都不缺席, 無論你在台北哪個角落都能輕鬆回家.󠀠 󠀠 每個房間都有對外窗, 近9成設備皆是全新搬入.󠀠 󠀠 🚲 YouBike 3分鐘 Ubike到 錦州街美食區 3分鐘 Ubike到 中山國中捷運站 3分鐘 Ubike到 南京復興捷運站 4分鐘 Ubike到 行天宮捷運站 4分鐘 Ubike到 遼寧夜市 5分鐘 Ubike到 錢櫃松江 6分鐘 Ubike到 長春國賓影城 󠀠 󠀠 📌地點: 中山區 龍江路229巷 3樓 公寓 📌格局: 1廚1廳2陽台2衛浴 (4雅1套) 📌設備: 冷氣、單/雙人床、衣櫃、桌椅、蒸氣洗衣機、冰箱、瓦斯爐、抽油煙機、熱水器、濾水器、120M網路&WIFI 📌租金包含: 網路費、垃圾代收費
